Workbook
Name \a: #REF!
Name CABLE: #REF!
Name CC: #REF!
Name EATET: #REF!
Name Excel_BuiltIn_Print_Area_1: #REF!
Name Excel_BuiltIn_Print_Titles_3: #REF!
Name Excel_BuiltIn_Print_Titles_4: #REF!
Name Excel_BuiltIn_Print_Titles_7: #REF!
Name FRNN: #REF!
Name MATICECODE: #REF!
Name MATRICE: #REF!
Name MODELE: #REF!
Name PGA: #REF!
Name RANGE1: '[1]Cable-data'!$A$8:$K$23
Name RANGE2: '[2]Cable-data'!$A$33:$K$48
Name RANGE3: '[3]Cable-data'!$A$55:$K$70
Name RANGE4: '[4]Cable-data'!$A$33:$K$48
Name RANGE5: '[4]Cable-data'!$A$33:$K$48
Name RANGE6: '[5]CABLE DATA'!$A$31:$C$46
Name RANGE7: '[4]Cable-data'!$A$33:$K$48
Name RANGE8: '[4]Cable-data'!$A$33:$K$48
Name RANGE9: '[4]Cable-data'!$A$33:$K$48
Name RYY5Y: #REF!

Sheet Summary
A1: SUMMARY SHEET
A3: SL.No | B3: DESCRIPTION | C3: TOTAL AMOUNT | D3: RATE PER SQFT
D4: =ROUND(37575.27786,2) -> 37575.28
A5: 1 | B5: CIVIL & INTERIOR | C5: ='Summary- C&I'!C17 -> 82578609 | D5: =C5/$D$4 -> 2197.6845
A6: =A5+1 -> 2 | B6: ELECTRICAL | C6: ='Summary Electrical '!E20 -> 13295070 | D6: =C6/$D$4 -> 353.82491
A7: =A6+1 -> 3 | B7: LIGHT FIXTURES | C7: ='Summary Electrical '!E22 -> 4700000 | D7: =C7/$D$4 -> 125.08223
A8: =A7+1 -> 4 | B8: NETWORK | C8: ='Summary Electrical '!E26 -> 2930397.5 | D8: =C8/$D$4 -> 77.987376
A9: =A8+1 -> 5 | B9: CCTV | C9: ='Summary Electrical '!E27 -> 741914 | D9: =C9/$D$4 -> 19.744736
A10: =A9+1 -> 6 | B10: ACS | C10: ='Summary Electrical '!E28 -> 210700 | D10: =C10/$D$4 -> 5.60741
A11: =A10+1 -> 7 | B11: LMS System | C11: ='Summary Electrical '!E29 -> 1115760 | D11: =C11/$D$4 -> 29.69399
A12: =A11+1 -> 8 | B12: HVAC | C12: ='HVAC Cost-Summary'!C8 -> 14039993 | D12: =C12/$D$4 -> 373.64972
A13: =A12+1 -> 9 | B13: FIRE & SAFETY | C13: =Sprinkler!G34 -> 2425066 | D13: =C13/$D$4 -> 64.538867
A14: =A13+1 -> 10 | B14: PHE WORK | C14: ='PHE Cost-Summary'!$C$9 -> 3428797 | D14: =C14/$D$4 -> 91.251403
A15: =A14+1 -> 11 | B15: EXTERNAL FURNITURE | C15: ='Outdoor Furniture'!F14 -> 2341875 | D15: =C15/$D$4 -> 62.324885
B17: TOTAL | C17: =SUM(C4:C16) -> 1.2780818e+08 | D17: =C17/$D$4 -> 3401.39
B18: GST-18% | C18: =C17*18% -> 23005473
B19: GRAND TOTAL | C19: =SUM(C17:C18) -> 1.5081365e+08

Sheet Summary- C&I
A1: SUMMARY SHEET
A3: SL.No | B3: DESCRIPTION | C3: TOTAL AMOUNT
A5: 1 | B5: Civil Work | C5: ='BOQ-C&I'!G47 -> 2445286.5
A6: 2 | B6: Flooring | C6: ='BOQ-C&I'!G112 -> 10198405
A7: 3 | B7: Ceiling | C7: ='BOQ-C&I'!G248 -> 5418443
A8: 4 | B8: Partition | C8: ='BOQ-C&I'!G348 -> 21727072
A9: 5 | B9: Doors | C9: ='BOQ-C&I'!G373 -> 3818750
A10: 6 | B10: Coustom Furniture | C10: ='BOQ-C&I'!G429 -> 5777491.8
A11: 7 | B11: Painting | C11: ='BOQ-C&I'!G463 -> 4068562
A12: 8 | B12: Miscelleneous | C12: ='BOQ-C&I'!G545 -> 3594484
A13: 9 | B13: Modular Furniture | C13: =Modular!G74 -> 21214157
A14: 11 | B14: Toilet Work | C14: ='Toilet Work'!F82 -> 3865958
A15: 12 | B15: Kitchen Equipment | C15: ='Kitchen Equipment'!G9 -> 450000
B17: TOTAL | C17: =SUM(C5:C16) -> 82578609

Sheet BOQ-C&I
A1: BOQ for Interior fitouts work
A3: Sl.No | B3: Description | C3: Basic Rate | D3: Unit | E3: TOTAL | F3: Rate | G3: Amount
A4: 1 | B4: CIVIL WORK
A5: =A4+0.01 -> 1.01 | B5: PEST CONTROL | D5: Sqm | E5: 3102 | F5: 67 | G5: =F5*E5 -> 207834
B6: Providing Pest control and Anti-termite treatment by appointing a specialised agency as per the specifications mentioned by the Bureau of Indian Standards and Agencies specifications
A8: =A5+0.01 -> 1.02 | B8: SCREED FLOORING | D8: Sqm | E8: 1531.5 | F8: 673 | G8: =F8*E8 -> 1030699.5
B9: Providing and laying PCC screed up to 30 mm avg Ht. of cement concrete ratio 1:3:6 (1unit cement, 3units- sand, 6units- course aggregate) in necessary level & slope, finished smoothly with 6-8mm thick. Layer of cement mortar of 1:1 mix (1unit- cement, 1unit- Fine screened sand) in power float finish with proper curing by logging water or sprinkling water or by laying wet gunny bags etc complete as directed. The cost includes Scaffolding all ancillary works as per base builders guidelines and as per site condition .
A11: =A8+0.01 -> 1.03 | B11: 150mm THICK SOLID BLOCK WALL | D11: Sqm | E11: 288 | F11: 1816 | G11: =F11*E11 -> 523008
B12: Making 150mm thick wall of Solid concrete Block in 1:4 cement mortar, with 2 nos. of 8 mm diameter steel reinforcement in every 4 layer & 2 nos. of hoop iron strips 25mm x 1.6mm, painted with anti-corrosive paint, RCC Lintel at 2400 mm Ht, properly bent and bonded at the end, inclusive of shuttering, scaffolding, Raking of joints and proper curing etc complete. The joints between the RCC and masonry will have hold fasts @ 600mm c/c, with joints finished in chicken mesh 20 gauge and finished with cement plaster
A14: =A11+0.01 -> 1.04 | B14: 100mm THICK SOLID BLOCK WALL | D14: Sqm | E14: 0 | F14: 1547 | G14: =F14*E14 -> 0
B15: Making 150mm thick wall of Solid concrete Block in 1:4 cement mortar, with 2 nos. of 8 mm diameter steel reinforcement in every 4 layer & 2 nos. of hoop iron strips 25mm x 1.6mm, painted with anti-corrosive paint, RCC Lintel at 2400 mm Ht, properly bent and bonded at the end, inclusive of shuttering, scaffolding, Raking of joints and proper curing etc complete. The joints between the RCC and masonry will have hold fasts @ 600mm c/c, with joints finished in chicken mesh 20 gauge and finished with cement plaster
A17: =A11+0.01 -> 1.04 | B17: CEMENT PLASTERING | D17: Sqm | E17: 187 | F17: 484 | G17: =F17*E17 -> 90508
B18: Providing & applying in one coat 12mm thick rough Cement plaster in proper line & level on internal surface of RCC/Bricks/Blocks walls with cement mortar 1:4 finished rough to take on POP punning. Rate shall be inclusive of scaffolding, grooves ,sills, band, curing, surface preparation before the application of plaster.
A20: =A11+0.01 -> 1.04 | B20: GYPROC PLASTER | D20: Sqm | E20: 414 | F20: 471 | G20: =F20*E20 -> 194994
B21: Providing & applying in one coat 12mm thick gyproc plaster in proper line & level on internal surface of RCC/Bricks/Blocks walls with gypsum punning. Rate shall be inclusive of scaffolding, grooves ,sills, band, curing, surface preparation before the application of plaster.
A23: =A20+0.01 -> 1.05 | B23: RCC LINTEL | D23: Rmt | E23: 14 | F23: 1046 | G23: =F23*E23 -> 14644
B24: Providing and laying 150/200x150/200x150/200mm lintel concrete by using reinforced cement concrete of nominal mix 1:1.5:3,The work includes concrete laying, shuttering, scaffolding, curing, 4Nos of 8mm dia Reinforement, etc complete as per the EIC.
A26: =A23+0.01 -> 1.06 | B26: WATER PROOFING | D26: Sqm | E26: 91 | F26: 1009 | G26: =F26*E26 -> 91819
B27: Providing and applying water proofing treatment on sunken / raised areas of toilets, etc. with three coats of tapecrete and sealing all junction, corners and joints of pipes after first coat with epoxy mortar as per approved specifications of the specialist agency including providing 10 years written guarantee against any defects and leakage. (Tapecrete is polymer modified cementious material being manufactured in collaboration with FRC Composite Ltd. Canada. It shall have low permeability with a high resistance to cracking). The rate including over the wall facia to height of 600mm. Only floor area shall be measured and paid for this item
A29: =A26+0.01 -> 1.07 | B29: WATER PROOFING WITH WALL PROTECTION | D29: RMT | E29: 25 | F29: 636 | G29: =F29*E29 -> 15900
B30: Providing and applying water proofing treatment on sunken / raised areas of toilets, etc. with three coats of tapecrete and sealing all junction, corners and joints of pipes after first coat with epoxy mortar as per approved specifications of the specialist agency including providing 10 years written guarantee against any defects and leakage. (Tapecrete is polymer modified cementious material being manufactured in collaboration with FRC Composite Ltd. Canada. It shall have low permeability with a high resistance to cracking). The rate including over the wall facia to height of 600mm. Only floor area shall be measured and paid for this item
A32: =A26+0.01 -> 1.07 | B32: CINDER FILLING | D32: Cum | E32: 14 | F32: 13889 | G32: =F32*E32 -> 194446
B33: Providing cinder filling for the sunken portions a toilet sunken slab and wherever specified with cement mortar 1:3 with approved waterproofing compound including compacting, then the layer of cinder and then surface finishing with cement mortar 1:3 with waterproofing compound evenly to take floor finishing (tiles), inclusive of all leads and lifts, levelling, curing etc. complete as per directions of engineer-in charge
A35: =A32+0.01 -> 1.08 | B35: SCREED CONCRETE OVER CINDER | D35: Sqm | E35: 50 | F35: 673 | G35: =F35*E35 -> 33650
B36: Providing & laying plain cement concrete 1:3:6 for a mimumum thickness of 40mm over prepared bed in toilets with 12mm down size aggregates including the cost of all materials, labour, compaction, levelling, at all levels, leads and lifts, curing, shuttering etc. complete as per instruction of Engineer-in charge
A38: =A35+0.01 -> 1.09 | B38: PLATE DROP OPENING | D38: Nos | E38: 1 | F38: 5699 | G38: =F38*E38 -> 5699
B39: Providing and Fixing Window opening of size 1600 x 450mm , The thickness of the wall ( 150mm ) all round the window to be finished with 18mm thk approved granite, edges chamfered. Complete as per detailed drawing and instructions of the Architect | C39: Basic Rate - 200/Sqft
A41: =A38+0.01 -> 1.1 | B41: GRANITE DOOR JAM | D41: Rmt | E41: 21 | F41: 1390 | G41: =F41*E41 -> 29190
B42: Providing and Fixing Granite door jam , The thickness of the wall ( 150mm ) all round the Door opening to be finished with 18mm thk approved granite, edges chamfered. Complete as per detailed drawing and instructions of the Architect | C42: Basic Rate - 200/Sqft
A44: =A41+0.01 -> 1.11 | B44: GRANITE STEPS | D44: Sqm | E44: 1 | F44: 12895 | G44: =F44*E44 -> 12895
B45: Providing and Fixing Granite Steps , The steps are bulid by solid block a solid block with 150mm riser & 300mm tread to be finished with 18mm thk approved granite, edges chamfered. Complete as per detailed drawing and instructions of the Architect | C45: Basic Rate - 200/Sqft
B47: SUB TOTAL CARRIED TO SUMMARY | G47: =SUM(G4:G46) -> 2445286.5
A48: 3 | B48: FLOORING
A50: =A48+0.01 -> 3.01 | B50: TILE FLOORING | D50: Sqm | E50: 257 | F50: 2125 | G50: =F50*E50 -> 546125
B51: Providing and laying to pattern, 10mm thick tile flooring Tiling using tiles of size given below , colour and make to pattern over Adhesive of make Latricrete / Polyglaze including joints shall be pointed with the matching cement based polymer grout as recommended by Laticrete/ Ardex Endura or approved equivalent, etc., Allow for protective plastic sheet to protect the tile till the handing over, the rate inclusive of providing necessary spacers to ensure uniform joints etc. complete. Rate including Materials, Manpower, Machinery, Tools, Transportation, Shifting to the required location, all wastages like design, pattern and handling, Lead and Lifts and all other necessary works required to complete full scope of Job at all locations and levels as per drawings and technical specifications. | C51: Basic Rate - 65/Sqft
A53: =A50+0.01 -> 3.02 | B53: Same as above 3.01 Tile Flooring | C53: Basic Rate -50/Sqft | D53: Sqm | E53: 93 | F53: 1899 | G53: =F53*E53 -> 176607
A55: =A53+0.01 -> 3.03 | B55: Same as above 3.01 Tile Flooring | C55: Basic Rate -60/Sqft | D55: Sqm | E55: 0 | F55: 2049 | G55: =F55*E55 -> 0
A57: =A55+0.01 -> 3.04 | B57: Same as above 3.01 Tile Flooring | C57: Basic Rate -200/Sqft | D57: Sqm | E57: 93 | F57: 4163 | G57: =F57*E57 -> 387159
A59: =A55+0.01 -> 3.04 | B59: VINYL FLOORING
B60: Providing & laying 3mm thick vinyl flooring over existing floor surface to proper level, line including joint treatment, complete as per detail drawing & Architect's instruction. Cost to include provididng and laying Self levelling screed 3-5 mm thk under the vinyl flooring. | C60: Basic Rate - 240/Sqft | D60: Sqm | E60: 755 | F60: 4400 | G60: =F60*E60 -> 3322000
...

Sheet M Sheet
A1: Civil Work Measurement Sheet
A2: Sl.No | B2: Description | C2: Unit | D2: Nos | E2: Length | F2: Width | G2: Height | H2: Total QTY
A4: 1 | B4: Pest Control | C4: Sqm
C5: Sqm | D5: 1 | E5: 56.55 | F5: 46.1 | H5: =PRODUCT(D5:G5) -> 2606.955
C6: Sqm | D6: 0.5 | E6: 24.47 | F6: 2.037 | H6: =PRODUCT(D6:G6) -> 24.922695
B7: Kitchen Deduction | C7: Sqm | D7: -1 | E7: 11 | F7: 9.8 | H7: =PRODUCT(D7:G7) -> -107.8
B8: Electrical & AHU Room | C8: Sqm | D8: -1 | E8: 14.5 | F8: 9 | H8: =PRODUCT(D8:G8) -> -130.5
B9: Balcony | C9: Sqm | D9: -1 | E9: 3.3 | F9: 7.9 | H9: =PRODUCT(D9:G9) -> -26.07
B10: Toilet | C10: Sqm | D10: -1 | E10: 6 | F10: 11.25 | H10: =PRODUCT(D10:G10) -> -67.5
B11: Ladies Toilet | C11: Sqm | D11: -1 | E11: 4 | F11: 9.67 | H11: =PRODUCT(D11:G11) -> -38.68
B12: Gents Toilet | C12: Sqm | D12: -1 | E12: 3.95 | F12: 12.42 | H12: =PRODUCT(D12:G12) -> -49.059
B13: Outdoor Seating | C13: Sqm | D13: -1 | E13: 7.6 | F13: 7.786 | H13: =PRODUCT(D13:G13) -> -59.1736
C14: Sqm | D14: -1 | E14: 4.115 | F14: 3.9 | H14: =PRODUCT(D14:G14) -> -16.0485
C15: Sqm | D15: -1 | E15: 3.15 | F15: 22.7 | H15: =PRODUCT(D15:G15) -> -71.505
B16: Near Staircase | C16: Sqm | D16: 1 | E16: 10.85 | F16: 21.65 | H16: =PRODUCT(D16:G16) -> 234.9025
B17: AHU Room | C17: Sqm | D17: -1 | E17: 7.1 | F17: 6.2 | H17: =PRODUCT(D17:G17) -> -44.02
C18: Sqm | D18: 1 | E18: 1.9 | F18: 0.6 | H18: =PRODUCT(D18:G18) -> 1.14
B19: Corner | C19: Sqm | D19: -1 | E19: 1.3 | F19: 15.09 | H19: =PRODUCT(D19:G19) -> -19.617
C20: Sqm | D20: 1 | E20: 12.25 | F20: 23.775 | H20: =PRODUCT(D20:G20) -> 291.24375
B21: Infront of Stair | C21: Sqm | D21: 1 | E21: 1.5 | F21: 1.1 | H21: =PRODUCT(D21:G21) -> 1.65
B22: Infront of Toilet | C22: Sqm | D22: 1 | E22: 3.4 | F22: 1.7 | H22: =PRODUCT(D22:G22) -> 5.78
C23: Sqm | D23: 1 | E23: 13.1 | F23: 26.175 | H23: =PRODUCT(D23:G23) -> 342.8925
B24: Triangle Portion | C24: Sqm | D24: 0.5 | E24: 3.81 | F24: 1.11 | H24: =PRODUCT(D24:G24) -> 2.11455
C25: Sqm | D25: -0.5 | E25: 7.7 | F25: 2.158 | H25: =PRODUCT(D25:G25) -> -8.3083
B26: AHU & Electrical Room Front | C26: Sqm | D26: 1 | E26: 0.8 | F26: 1.9 | H26: =PRODUCT(D26:G26) -> 1.52
C27: Sqm | D27: 1 | E27: 6.6 | F27: 6.625 | H27: =PRODUCT(D27:G27) -> 43.725
C28: Sqm | D28: 1 | E28: 0.8 | F28: 3.75 | H28: =PRODUCT(D28:G28) -> 3
B29: Ladies Toilet | C29: Sqm | D29: 1 | E29: 11.05 | F29: 4.15 | H29: =PRODUCT(D29:G29) -> 45.8575
C30: Sqm | D30: -1 | E30: 1.3 | F30: 1.85 | H30: =PRODUCT(D30:G30) -> -2.405
C31: Sqm | D31: -1 | E31: 2.25 | F31: 4.24 | H31: =PRODUCT(D31:G31) -> -9.54
B32: PH Toilet | C32: Sqm | D32: 1 | E32: 2.4 | F32: 2.15 | H32: =PRODUCT(D32:G32) -> 5.16
C33: Sqm | D33: 1 | E33: 1.25 | F33: 2.4 | H33: =PRODUCT(D33:G33) -> 3
B34: Gents Toilet | C34: Sqm | D34: 1 | E34: 12.22 | F34: 4.15 | H34: =PRODUCT(D34:G34) -> 50.713
C35: Sqm | D35: -1 | E35: 2.32 | F35: 0.6 | H35: =PRODUCT(D35:G35) -> -1.392
B36: Gents Toilet -2 | C36: Sqm | D36: 1 | E36: 11.2 | F36: 4.15 | H36: =PRODUCT(D36:G36) -> 46.48
C37: Sqm | D37: 1 | E37: 2.54 | F37: 1.25 | H37: =PRODUCT(D37:G37) -> 3.175
B38: PH Toilet 02 | C38: Sqm | D38: 1 | E38: 2.54 | F38: 2.15 | H38: =PRODUCT(D38:G38) -> 5.461
B39: Ladies Toilet -2 | C39: Sqm | D39: 1 | E39: 11.2 | F39: 4.15 | H39: =PRODUCT(D39:G39) -> 46.48
C40: Sqm | D40: -1 | E40: 1.3 | F40: 1.95 | H40: =PRODUCT(D40:G40) -> -2.535
C41: Sqm | D41: -1 | E41: 4.44 | F41: 2.25 | H41: =PRODUCT(D41:G41) -> -9.99
...

Sheet Modular
A1: BOQ for Interior Furniture
A3: Sl.No | B3: Description | C3: LOCATION | D3: Unit | E3: TOTAL | F3: Rate | G3: Amount
B4: MODULAR FURNITURE
A5: 1 | B5: Linear workstation (1350 x 750mm) | D5: Nos | E5: =33+48+4+8+8+40+8+12+18+2+1+6+39+16+15+1 -> 259 | F5: 9750 | G5: =F5*E5 -> 2525250
A6: =A5+1 -> 2 | B6: Linear workstation with Shelves (1350 x 750mm) | D6: Nos | E6: 0 | F6: 10625 | G6: =F6*E6 -> 0
A7: =A6+1 -> 3 | B7: Height Adjustable work station (1350 x 750mm) | D7: Nos | E7: 21 | F7: 36875 | G7: =F7*E7 -> 774375
A8: =A7+1 -> 4 | B8: L Shape work station (1500 x 1200mm) | D8: Nos | E8: 12 | F8: 20375 | G8: =F8*E8 -> 244500
A9: =A8+1 -> 5 | B9: Pedestal Unit | D9: Nos | E9: =E5+E6+E8+2 -> 273 | F9: 4000 | G9: =F9*E9 -> 1092000
A10: =A9+1 -> 6 | B10: Manager Cabin with Storage unit (2100 x 2100mm) | D10: Nos | E10: 12 | F10: 31250 | G10: =F10*E10 -> 375000
A11: =A10+1 -> 7 | B11: CEO Cabin Table with Side Storage (2100 x 2100mm) | D11: Nos | E11: 1 | F11: 47500 | G11: =F11*E11 -> 47500
A12: =A11+1 -> 8 | B12: Movable & foldable workstation (1650 x 600mm) | D12: Nos | E12: 24 | F12: 31250 | G12: =F12*E12 -> 750000
A13: =A12+1 -> 9 | B13: 8 Pax Table (3000 x 1200mm) | D13: Nos | E13: 2 | F13: 31250 | G13: =F13*E13 -> 62500
A14: =A13+1 -> 10 | B14: 6 Pax Table (2200 x 1200mm) | D14: Nos | E14: 3 | F14: 21875 | G14: =F14*E14 -> 65625
A15: =A14+1 -> 11 | B15: 4 Pax circular Table (1200mm) | D15: Nos | E15: 3 | F15: 13750 | G15: =F15*E15 -> 41250
A16: =A15+1 -> 12 | B16: 3 Pax circular Table (900mm) | D16: Nos | E16: 3 | F16: 10625 | G16: =F16*E16 -> 31875
A17: =A16+1 -> 13 | B17: 15 Pax Table (5620 x 1600mm) | D17: Nos | E17: 1 | F17: 65000 | G17: =F17*E17 -> 65000
A18: =A17+1 -> 14 | B18: Linear Table (1200 x 600mm) | D18: Nos | E18: 8 | F18: 8125 | G18: =F18*E18 -> 65000
A19: =A18+1 -> 15 | B19: Café Table (1200 x 750mm) | D19: Nos | E19: 19 | F19: 18750 | G19: =F19*E19 -> 356250
A20: =A19+1 -> 16 | B20: Café Table (1800 x 750mm) | D20: Nos | E20: 4 | F20: 18750 | G20: =F20*E20 -> 75000
A21: =A20+1 -> 17 | B21: 1200mm Dia Café Table | D21: Nos | E21: 5 | F21: 17500 | G21: =F21*E21 -> 87500
A22: =A21+1 -> 18 | B22: Booth Table | D22: Nos | E22: 5 | F22: 11875 | G22: =F22*E22 -> 59375
B25: CHAIRS
A26: =A22+1 -> 19 | B26: Work Station Chairs : Back Height - Medium Back Back Finish - HNI Standard Response Mesh with adjustable lumbar support Back Frame - Black Color Seat Finish - HNI Standard Fabric Seat Height Adjustment - Pneumatic Mechanism - Weight activated with Seat depth Back Tilt Lock - Mutipoint Lock (3 point Lock) Back Tilt Tension - Adjustable Armrests Type - 3D Adjustable arms Armpads Type - Polyurethane Base Type - 5-Star in black nylon base Greenguard Certified Product BIFMA Certified : (ANSI/BIFMA-X5.1-2017) LCA & EPD Certifications WARRANTY: 10 Years from the date of invoice | D26: Nos | E26: 381 | F26: 11000 | G26: =F26*E26 -> 4191000
A27: =A26+1 -> 20 | B27: VP Cabin Chairs: Back Height - High Back (with Headrest) Back Finish - HNI Standard Response Mesh with adjustable lumbar support Back Frame - Black Color Seat Finish - HNI Standard Fabric Seat Height Adjustment - Pneumatic Mechanism - Weight activated with Seat depth Back Tilt Lock - Mutipoint Lock (3 point Lock) Back Tilt Tension - Adjustable Armrests Type - 3D Adjustable arms Armpads Type - Polyurethane Base Type - 5-Star in black nylon base Greenguard Certified Product BIFMA Certified : (ANSI/BIFMA-X5.1-2017) LCA & EPD Certifications WARRANTY: 10 Years from the date of invoice | C27: VP Cabin | D27: Nos | E27: 12 | F27: 13500 | G27: =F27*E27 -> 162000
A28: =A27+1 -> 21 | B28: Meeting Room Chairs (Equivalent to Helix) : Specification: Back Height - High Back (with Headrest) Back Finish - HNI Standard Response Mesh with adjustable lumbar support Back Frame - Black Color Seat Finish - HNI Standard Fabric Seat Height Adjustment - Pneumatic Mechanism - Weight activated with Seat depth Back Tilt Lock - Mutipoint Lock (3 point Lock) Back Tilt Tension - Adjustable Armrests Type - 4D Adjustable arms Armpads Type - Polyurethane Base Type - 5-Star in black nylon base Greenguard Certified Product BIFMA Certified : (ANSI/BIFMA-X5.1-2017) LCA & EPD Certifications WARRANTY: 10 Years from the date of invoice | C28: Board Room, CEO & Founder Cabin | D28: Nos | E28: 17 | F28: 31250 | G28: =F28*E28 -> 531250
A29: =A28+1 -> 22 | B29: Training Room Chairs | C29: Training Room | D29: Nos | E29: 42 | F29: 17500 | G29: =F29*E29 -> 735000
A30: =A29+1 -> 23 | B30: Café Chairs with Arm rest | D30: Nos | E30: 20 | F30: 5313 | G30: =F30*E30 -> 106260
A31: 24 | B31: Café Chairs without Arm rest | D31: Nos | E31: 44 | F31: 4938 | G31: =F31*E31 -> 217272
B33: LOOSE FURNITURE
A34: =A31+1 -> 25 | B34: Center Table - 600mm Dia | C34: Wellness Room, Media byte Room & VR Room | D34: Nos | E34: 4 | F34: 13750 | G34: =F34*E34 -> 55000
A35: =A34+1 -> 26 | B35: Center Table - 600mm Dia x 750mm Height | C35: War Room ; 2 Pax | D35: Nos | E35: 3 | F35: 13750 | G35: =F35*E35 -> 41250
A36: =A35+1 -> 27 | B36: Center Table - 600mm Dia | C36: Bench Seating | D36: Nos | E36: 1 | F36: 13750 | G36: =F36*E36 -> 13750
A37: =A36+1 -> 28 | B37: Center Table - 600mm Dia - Double Table | C37: Reception | D37: Nos | E37: 1 | F37: 31250 | G37: =F37*E37 -> 31250
A38: =A37+1 -> 29 | B38: Center Table - 670mm Dia | C38: Collab Area | D38: Nos | E38: 6 | F38: 13750 | G38: =F38*E38 -> 82500
A39: =A38+1 -> 30 | B39: Center Table - 800mm Dia | C39: Reception | D39: Nos | E39: 1 | F39: 15000 | G39: =F39*E39 -> 15000
A40: =A39+1 -> 31 | B40: Center Table - 900mm Dia | C40: Collab Near CEO | D40: Nos | E40: 1 | F40: 15000 | G40: =F40*E40 -> 15000
A41: =A40+1 -> 32 | B41: Single seater sofa | C41: Founder Cabin | D41: Nos | E41: 2 | F41: 22500 | G41: =F41*E41 -> 45000
A42: =A41+1 -> 33 | B42: Single seater sofa | C42: 2 Pax meeting Room | D42: Nos | E42: 2 | F42: 16250 | G42: =F42*E42 -> 32500
A43: =A42+1 -> 34 | B43: Single seater sofa | C43: Media Byte Room | D43: Nos | E43: 2 | F43: 17500 | G43: =F43*E43 -> 35000
A44: =A43+1 -> 35 | B44: Single seater sofa | C44: Collab Near CEO | D44: Nos | E44: 1 | F44: 16875 | G44: =F44*E44 -> 16875
...

Sheet Outdoor Furniture
A1: BOQ for Interior Furniture
A3: Sl.No | B3: Description | C3: Unit | D3: TOTAL | E3: Rate | F3: Amount
B4: EXTERNAL FURNITURE
A5: 1 | B5: Outdoor Café Table (1200mm x 800mm) | C5: Nos | D5: 20 | E5: 25000 | F5: =E5*D5 -> 500000
A6: 2 | B6: 1200mm Dia Café Table | C6: Nos | D6: 5 | E6: 27500 | F6: =E6*D6 -> 137500
A7: 3 | B7: Café Chair | C7: Nos | D7: =D6*4+12*4+3 -> 71 | E7: 5625 | F7: =E7*D7 -> 399375
A8: 4 | B8: Café Sofa | C8: Nos | D8: 14 | E8: 43750 | F8: =E8*D8 -> 612500
A9: 5 | B9: FRP Pot with Plants | C9: Rmt | D9: 28 | E9: 6875 | F9: =E9*D9 -> 192500
A10: 6 | B10: FRP Pot with Plants | C10: Nos | D10: 5 | E10: 6250 | F10: =E10*D10 -> 31250
A11: 7 | B11: CANOPY SERVICE WORK | C11: LS | D11: 1 | E11: 375000 | F11: =E11*D11 -> 375000
A12: 8 | B12: CAFÉ UMPERLLA | C12: Nos | D12: 5 | E12: 18750 | F12: =E12*D12 -> 93750
B14: Total Modular | F14: =SUM(F5:F13) -> 2341875

Sheet Toilet Work
A2: Sl.No | B2: Description | C2: Unit | D2: TOTAL | E2: Rate | F2: Amount
A3: 1.01 | B3: FLOOR CHIPPING | C3: sqm | D3: 87 | E3: 650 | F3: =E3*D3 -> 56550
B4: Chipping and removing of existing concrete with all necessary tools tackles, barricading of the work place, protection of existing finishes, cleaning of the workplace at the end of day's work, clearing of debris, disposing the debris in landfill site allocated by the Municipal Authorities outside the campus and preparing the place to receive the next finish as required, complete as per Project Manager's instructions..
A6: =A3+0.01 -> 1.02 | B6: CONTRUCTION OF 150MM THICK SIZE SOLID BLOCK MASONRY | C6: sqm | D6: 21 | E6: 1816 | F6: =E6*D6 -> 38136
B7: Making 150mm thick wall of Solid concrete Block in 1:4 cement mortar, with 2 nos. of 8 mm diameter steel reinforcement in every 4 layer & 2 nos. of hoop iron strips 25mm x 1.6mm, painted with anti-corrosive paint, RCC Lintel at 2400 mm Ht, properly bent and bonded at the end, inclusive of shuttering, scaffolding, Raking of joints and proper curing etc complete. The joints between the RCC and masonry will have hold fasts @ 600mm c/c, with joints finished in chicken mesh 20 gauge and finished with cement plaster
A9: =A6+0.01 -> 1.03 | B9: PLASTERING | C9: sqm | D9: 205 | E9: 471 | F9: =E9*D9 -> 96555
B10: Providing and applying in one coat, avg 12-15mm thick plaster on internal surface of RCC / brick / block walls in cement mortar 1:4, complete to true line & plumb in all levels and locations & finished rough to take on POP punning. Rate shall include for scaffolding, making grooves, sills, pattas, curing, surface preparation before the application of plaster, providing galvanized chicken mesh to a width of 150 mm at the junctions of masonry and RCC structure (column to wall, wall to beam, lintel to beam, corners of walls/columns etc. complete) including tying in position by using suitable nails / clamps / screws and as directed etc. complete at all levels. The contractor shall make good the grooves, pockets etc. after the scaffolding is removed.
A12: =A9+0.01 -> 1.04 | B12: WATERPROOFING | C12: Sqm | D12: 133 | E12: 1009 | F12: =E12*D12 -> 134197
B13: Providing of water proofing - chemical Treatment – the slab to be cleaned and apply 3 coats of chemical on the floor and on the peripheral walls up to 900mm. Base coat – Applying base coat of 1:6 mortar over chemical treatment on the floor and on the peripheral walls up to 450mm.Cost of the water proofing shall include cleaning of the surface of all dirt and grit before the application. The water proofed area shall be ponded and tested for a minimum of 24 hours or as per manufacturer's specification. Note - Warranty to be provided up to 10 years
B14: Clean surface to remove all dust, foreign matters, loose particles or any deposits of contaminants which could affect the bond between the surface and waterproof coating.
B15: Remove all sharp projections and make surface reasonably smooth
B16: Thoroughly pre-wet all concrete surfaces for at least one hour prior to application of coating, by ponding of water on flat surfaces and by vigorous spraying of water on vertical surfaces.
B17: Remove all water from surfaces prior to applying of water proof coating, so that the surface is only damp or surface dry. Standing water or shiny wet surface shall not be present under any circumstances
B18: Apply water proof coating / Brush Topping as specified for various conditions.
B19: Apply 12mm thick cement plaster 1:4 (1cement : 4 coarse sand) after applications of final coat.
B20: After application of final coat of Tape Crete, allow to air dry for 4-6 hours. Do not use any water for curing during this time.
B21: In case of high temperatures and low humidity combined with high wind condition, cover the coating with polythene sheet to prevent rapid drying.
B22: Maximum 6 hours after final application, moist cure for 24 hours by spraying water. Ensure that at no time during this 24 hour period the coating is completely dry or completely submerged in water.
B23: After moist curing, allow to air dry for 3 days.
B24: After air drying, complete the curing by submersion in water for 24 hours.
B25: Make : Fosroc , Sika India Pvt.Ltd
A27: =A12+0.01 -> 1.05 | B27: CINDER FILLING | C27: cum | D27: 27 | E27: 13889 | F27: =E27*D27 -> 375003
B28: Providing cinder filling for the sunken portions a toilet sunken slab and wherever specified with cement mortar 1:3 with approved waterproofing compound including compacting, then the layer of cinder and then surface finishing with cement mortar 1:3 with waterproofing compound evenly to take floor finishing (tiles), inclusive of all leads and lifts, levelling, curing etc. complete as per directions of engineer-in charge
A30: =A27+0.01 -> 1.06 | B30: SCREED CONCRETE OVER CINDER | C30: Sqm | D30: 87 | E30: 673 | F30: =E30*D30 -> 58551
B31: Providing & laying plain cement concrete 1:3:6 for a mimumum thickness of 40mm over prepared bed in toilets with 12mm down size aggregates including the cost of all materials, labour, compaction, levelling, at all levels, leads and lifts, curing, shuttering etc. complete as per instruction of Engineer-in charge
A33: =A30+0.01 -> 1.07 | B33: WASH BASIN COUNTER - GRANITE | C33: Rmt | D33: 13 | E33: 8659 | F33: =E33*D33 -> 112567
B34: Providing and fixing storage unit with 690mm wide 12 mm thk corian counter top of approved shade garnite to be fixed over on MS support & made of 18mm thk BWR Ply board. as per detailed drawing. Cost inclusive of 150mm high Backspalsh band above counter to mount powet / data sockets as per detail dwg . Make of Ply - Greenply, Archidply . Make of Laminate - Merino, Greenlam, Century .
A36: =A33+0.01 -> 1.08 | B36: VITRIFIED TILE FLOORING | C36: sqm | D36: 87 | E36: 2099 | F36: =E36*D36 -> 182613
B37: Providing and laying vitrified tile flooring with 3mm Spacers over Laticrete Tile Adhisive 4-6mm thk. Joints between tiling to be filled with approved Epoxy grout of approved shade as per manufacturers specifications. Rate to include cost for laying tiles to approved pattern, design as directed by Architect, including curing, acid wash, etc.
A39: =A36+0.01 -> 1.09 | B39: GROUTING ON EXISTING TOILET TILE | C39: sqm | D39: 297 | E39: 269 | F39: =E39*D39 -> 79893
B40: Providing and laying approved Epoxy grout of approved shade as per manufacturers specifications.
A42: =A36+0.01 -> 1.09 | B42: SAME AS ABOVE TILE CLADDING | C42: Sqm | D42: 205 | E42: 3567 | F42: =E42*D42 -> 731235
A44: =A36+0.01 -> 1.09 | B44: GRANITE LEDGE | C44: Rmt | D44: 22 | E44: 923 | F44: =E44*D44 -> 20306
B45: Providing and Fixing , granit top of the ledge to be finished with 18mm thk approved granite, edges chamfered. Complete as per detailed drawing and instructions of the Architect
A47: =A44+0.01 -> 1.1 | B47: GRANITE DOOR JAM | C47: Rmt | D47: 24 | E47: 1845 | F47: =E47*D47 -> 44280
B48: Providing and Fixing , granit top of the ledge to be finished with 18mm thk approved granite, edges chamfered. Complete as per detailed drawing and instructions of the Architect
A50: =A47+0.01 -> 1.11 | B50: GRANITE RAMP | C50: Sqm | E50: 6391 | F50: =E50*D50 -> 0
B51: Providing and Fixing , granit top of the Ramp to be finished with 18mm thk approved granite, edges chamfered. Complete as per detailed drawing and instructions of the Architect
A53: =A50+0.01 -> 1.12 | B53: Granite Skirting | C53: Rmt | D53: 80 | E53: 923 | F53: =E53*D53 -> 73840
B54: Providing and Fixing , 100mm ht granit top of the Skirting to be finished with 18mm thk approved granite, edges chamfered. Complete as per detailed drawing and instructions of the Architect
...

Sheet Kitchen Equipment
A1: BOQ for Kitchen Equipmet
A3: Sl.No | B3: Description | C3: Reference Images | D3: Unit | E3: TOTAL | F3: Rate | G3: Amount
A4: 1 | B4: SS SINK COUNTER - Size (2100 x 1200) | D4: Nos | E4: 2 | F4: 56250 | G4: =F4*E4 -> 112500
A5: 2 | B5: SS STORAGE UNIT | D5: Sqm | E5: 13 | F5: 18750 | G5: =F5*E5 -> 243750
B6: SS STORAGE UNIT with Shuter | D6: Sqm | E6: 3 | F6: 31250 | G6: =F6*E6 -> 93750
A7: 3 | B7: Plate Rack | D7: Nos | E7: 0 | F7: 31250 | G7: =F7*E7 -> 0
B9: TOTAL | G9: =SUM(G4:G8) -> 450000

Sheet Summary  Electrical 
A1: Project: Indegene_3F
A2: Scope of Work : Electrical and ELV | E2: Area | F2: Date : 11.11.2025
A3: Purpose - Tender | E3: 0 | F3: Rev No : R0
A4: SUMMARY
A5: S.No | B5: Description | C5: Amount (Supply) | D5: Amount (Installation) | E5: Amount (Supply+Installation) | F5: Remarks
A7: A | B7: Electrical Works : internal
A8: 1 | B8: LT Switchgear : | C8: ='Internal Electrical Works '!G74 -> 153326 | D8: ='Internal Electrical Works '!H74 -> 9250 | E8: =C8+D8 -> 162576
A9: 2 | B9: MCB Distribution Boards : | C9: ='Internal Electrical Works '!G214 -> 501239 | D9: ='Internal Electrical Works '!H214 -> 29888 | E9: =C9+D9 -> 531127
A10: 3 | B10: Low Voltage Cables and End Termination : | C10: ='Internal Electrical Works '!G301 -> 709420 | D10: ='Internal Electrical Works '!H301 -> 56834 | E10: =C10+D10 -> 766254
A11: 4 | B11: Swicthes and Sockets : | C11: ='Internal Electrical Works '!G348 -> 1623704 | D11: ='Internal Electrical Works '!H348 -> 207997 | E11: =C11+D11 -> 1831701
A12: 5 | B12: Circuit Mains | C12: ='Internal Electrical Works '!G366 -> 4533550 | D12: ='Internal Electrical Works '!H366 -> 837350 | E12: =C12+D12 -> 5370900
A13: 6 | B13: Point Wiring | C13: ='Internal Electrical Works '!G378 -> 1387710 | D13: ='Internal Electrical Works '!H378 -> 541090 | E13: =C13+D13 -> 1928800
A14: 7 | B14: Cable Trays/Raceways | C14: ='Internal Electrical Works '!G439 -> 1577253 | D14: ='Internal Electrical Works '!H439 -> 304831 | E14: =C14+D14 -> 1882084
A15: 8 | B15: Earthing | C15: ='Internal Electrical Works '!G469 -> 226001 | D15: ='Internal Electrical Works '!H469 -> 52827 | E15: =C15+D15 -> 278828
A16: 9 | B16: Pipes (Electrical/IT/AV/CCTV/ACS) | C16: ='Internal Electrical Works '!G492 -> 149700 | D16: ='Internal Electrical Works '!H492 -> 93900 | E16: =C16+D16 -> 243600
A17: 10 | B17: Structural Works | C17: ='Internal Electrical Works '!G499 -> 10350 | D17: ='Internal Electrical Works '!H499 -> 5100 | E17: =C17+D17 -> 15450
A18: 11 | B18: Miscellaneous Works | C18: ='Internal Electrical Works '!G515 -> 53125 | D18: ='Internal Electrical Works '!H515 -> 230625 | E18: =C18+D18 -> 283750
C20: =SUM(C3:C18) -> 10925378 | D20: =SUM(D3:D18) -> 2369692 | E20: =SUM(E8:E19) -> 13295070
A22: B | B22: Light Fixtures | C22: =1200*3500 -> 4200000 | D22: 500000 | E22: =D22+C22 -> 4700000
A24: C | B24: UPS | C24: ='UPS-Indegene'!G12 -> 0 | D24: ='UPS-Indegene'!H12 -> 0 | E24: =C24+D24 -> 0
A26: D | B26: IT Networking | C26: =IT!G105 -> 2720115.7 | D26: =IT!H105 -> 210281.8 | E26: =C26+D26 -> 2930397.5
A27: E | B27: CCTV | C27: =CCTV!G32 -> 629072 | D27: =CCTV!H32 -> 112842 | E27: =C27+D27 -> 741914
A28: F | B28: Access Control System | C28: =ACS!G39 -> 166100 | D28: =ACS!H39 -> 44600 | E28: =C28+D28 -> 210700
A29: G | B29: LMS System | C29: ='LMS '!I13 -> 1064520 | D29: ='LMS '!J13 -> 51240 | E29: =C29+D29 -> 1115760
B32: Total Amount | E32: =SUM(E23:E31) -> 4998771.5
B33: GST
B34: Grand Total
B36: EXCLUSIONS:
B37: Software for ACS /Attendence management
B38: Fixed Deposit to Electricity board, Power Sanction and Approvals,Solar panels.
B39: Video conferencing / Display/ Projector - AV System related works
B40: Intrusion system
B41: Active Components & Servers, Switches, Rack for Access Control
B42: Novec/ Vesda system
B43: Isolation transformer for UPS
B44: Taxes shall be extra as applicable
B45: UPS - Existing UPS shall be utilised
... B47: IT / Networking Exclusion : Networking Active components , Software, Wi Fi devices, Server, Router, Active Switch, Firewall ,EPABX ,IT Equipment-. Printers, Fax, Photocopier,, Office Equipment, laptop, desktop, speaker phones etc

Sheet Internal Electrical Works 
A1: Project: Indegene_3F | I1: Date : 27.01.2026
A2: Electrical Works | I2: Rev No : R1
A4: Sl No | B4: ITEM DESCRIPTION | C4: UNIT | D4: Total QTY | E4: Rate | G4: Total Amount (Supply) | H4: Total Amount (Installation) | I4: Remarks
D5: Total | E5: Supply | F5: Installation
A7: 1 | B7: LT SWITCHGEAR
B9: Installation, testing and commissioning of Low voltage switchgear's, free standing, Cubical type, dead front, Frame and Doors:2mm, Internal Partations:1.6mm thick, Gland Plates:3mm Thick, powder coated (Paint Shade: RAL 7032/7035), indoor type with vermin proof hinged lockable doors for each compartment, bus bar interconnections for incoming and outgoing including feeders earthing and painting and as per specifications comprising of ACB,MCCB and MCB horizontal and vertical aluminum bus bar, earth bus bar as per SLD. All meters shall be digital with LED display, whereever mentioned and shall have RS 485 Modbus RTU half duplex communication interface for provision of BMS connectivity and wired accordingly. Provide required NO/NC potential free contacts wires and terminal blocks in the cable alley for BMS operation (Optional).The swtichboards are to be tested as per IS 8623 -1977 specifications. The busbars are of high conductivity Al. alloy E91E IS 5082 specification and cable entries will be from either top or bottom depending on location. LT Switchgear shall be as per technical specification and single line diagram
A11: 1.1 | B11: MDB -3F(S-1) | C11: Nos | D11: =1*0 -> 0 | E11: 312500 | F11: 62500 | G11: =IF($D11="","",IFERROR($D11*E11,"")) -> 0 | H11: =IF($D11="","",IFERROR($D11*F11,"")) -> 0
B12: MDB -3F (S-1) - Existing Panle modifications as per the Single line diagram and technical specifications.(Indoor -IP 42)
A14: 1.2 | B14: MDB -3F(S-2) | C14: Nos | D14: =1*0 -> 0 | E14: 250000 | F14: 22500 | G14: =IF($D14="","",IFERROR($D14*E14,"")) -> 0 | H14: =IF($D14="","",IFERROR($D14*F14,"")) -> 0
B15: MDB -3F (S-2) - Existing Panle modifications as per the Single line diagram and technical specifications.(Indoor -IP 42)
A17: 1.3 | B17: UPS I/P PANEL-1 | C17: Nos | D17: =1*0 -> 0 | E17: 62500 | F17: 18000 | G17: =IF($D17="","",IFERROR($D17*E17,"")) -> 0 | H17: =IF($D17="","",IFERROR($D17*F17,"")) -> 0
B18: UPS I/P PANEL-1 - Existing Panle modifications as per the Single line diagram and technical specifications.(Indoor -IP 42)
A20: 1.4 | B20: UPS I/P PANEL-2 | C20: Nos | D20: =1*0 -> 0 | E20: 62500 | F20: 18000 | G20: =IF($D20="","",IFERROR($D20*E20,"")) -> 0 | H20: =IF($D20="","",IFERROR($D20*F20,"")) -> 0
B21: UPS I/P PANEL-2 - Existing Panle modifications as per the Single line diagram and technical specifications.(Indoor -IP 42)
A23: 1.5 | B23: UPS O/P PANEL-1 | C23: Nos | D23: =1*0 -> 0 | E23: 31250 | F23: 18000 | G23: =IF($D23="","",IFERROR($D23*E23,"")) -> 0 | H23: =IF($D23="","",IFERROR($D23*F23,"")) -> 0
B24: UPS O/P PANEL -1 Existing Panle modifications as per the Single line diagram and technical specifications.(Indoor -IP 42)
A26: 1.6 | B26: UPS O/P PANEL-2 | C26: Nos | D26: =1*0 -> 0 | E26: 31250 | F26: 15000 | G26: =IF($D26="","",IFERROR($D26*E26,"")) -> 0 | H26: =IF($D26="","",IFERROR($D26*F26,"")) -> 0
B27: UPS O/P PANEL -2 Existing Panle modifications as per the Single line diagram and technical specifications.(Indoor -IP 42)
A29: 1.7 | B29: UPS O/P PANEL-3 | C29: Nos | D29: =1*0 -> 0 | E29: 31250 | F29: 15000 | G29: =IF($D29="","",IFERROR($D29*E29,"")) -> 0 | H29: =IF($D29="","",IFERROR($D29*F29,"")) -> 0
B30: UPS O/P PANEL -3 Existing Panle modifications as per the Single line diagram and technical specifications.(Indoor -IP 42)
A32: 1.7 | B32: UPS O/P PANEL-4 | C32: Nos | D32: =1*0 -> 0 | E32: 31250 | F32: 15000 | G32: =IF($D32="","",IFERROR($D32*E32,"")) -> 0 | H32: =IF($D32="","",IFERROR($D32*F32,"")) -> 0
B33: UPS O/P PANEL -4 Existing Panle modifications as per the Single line diagram and technical specifications.(Indoor -IP 42)
A35: 1.8 | B35: VRF AC Panel (Proposed) | C35: Nos | D35: =1*0 -> 0 | E35: 193750 | F35: 15000 | G35: =IF($D35="","",IFERROR($D35*E35,"")) -> 0 | H35: =IF($D35="","",IFERROR($D35*F35,"")) -> 0
B36: VRF AC Panel shall be as per Single line diagram and technical specifications.(Indoor -IP 42)
A38: 1.9 | B38: Kitchen (Proposed) | C38: Nos | D38: =1*0 -> 0 | E38: 156250 | F38: 15000 | G38: =IF($D38="","",IFERROR($D38*E38,"")) -> 0 | H38: =IF($D38="","",IFERROR($D38*F38,"")) -> 0
B39: Kitchen Panel shall be as per Single line diagram and technical specifications.(Indoor -IP 42)
A41: 1.1 | B41: Supply and installation of MCB ISOLATORS
A42: a | B42: 160A 4P MCCB in metallic enclosure -IP 42 (Without Release) | C42: Nos | D42: =4*0 -> 0 | E42: 27808 | F42: 5250 | G42: =IF($D42="","",IFERROR($D42*E42,"")) -> 0 | H42: =IF($D42="","",IFERROR($D42*F42,"")) -> 0
A43: b | B43: 80A 4P MCCB in metallic enclosure -IP 42 (Without Release) | C43: Nos | D43: =4*0 -> 0 | E43: 13780 | F43: 2250 | G43: =IF($D43="","",IFERROR($D43*E43,"")) -> 0 | H43: =IF($D43="","",IFERROR($D43*F43,"")) -> 0
A44: c | B44: 80A 4P MCB in metallic enclosure -IP 42 | C44: Nos | D44: 0 | E44: 11531 | F44: 1500 | G44: =IF($D44="","",IFERROR($D44*E44,"")) -> 0 | H44: =IF($D44="","",IFERROR($D44*F44,"")) -> 0
A45: d | B45: 80A 4P MCB in metallic enclosure -IP 65 | C45: Nos | D45: 0 | E45: 11531 | F45: 1500 | G45: =IF($D45="","",IFERROR($D45*E45,"")) -> 0 | H45: =IF($D45="","",IFERROR($D45*F45,"")) -> 0
A46: e | B46: 63A 4P MCB in metallic enclosure -IP 42 | C46: Nos | D46: 0 | E46: 6596 | F46: 1125 | G46: =IF($D46="","",IFERROR($D46*E46,"")) -> 0 | H46: =IF($D46="","",IFERROR($D46*F46,"")) -> 0
A47: f | B47: 63A 4P MCB in metallic enclosure -IP 65 (Suitable to terminate 16/25 sqmm Cables) | C47: Nos | D47: 6 | E47: 6596 | F47: 1125 | G47: =IF($D47="","",IFERROR($D47*E47,"")) -> 39576 | H47: =IF($D47="","",IFERROR($D47*F47,"")) -> 6750
A48: g | B48: 40A 4P MCB in metallic enclosure -IP 42 | C48: Nos | D48: 0 | E48: 6219 | F48: 750 | G48: =IF($D48="","",IFERROR($D48*E48,"")) -> 0 | H48: =IF($D48="","",IFERROR($D48*F48,"")) -> 0
A49: h | B49: 40A 4P MCB in metallic enclosure -IP 65 (Suitable to terminate 16/25 sqmm Cables) | C49: Nos | D49: 0 | E49: 6219 | F49: 750 | G49: =IF($D49="","",IFERROR($D49*E49,"")) -> 0 | H49: =IF($D49="","",IFERROR($D49*F49,"")) -> 0
A50: i | B50: 25A 4P MCB in metallic enclosure -IP 42 | C50: Nos | D50: 0 | E50: 4764 | F50: 750 | G50: =IF($D50="","",IFERROR($D50*E50,"")) -> 0 | H50: =IF($D50="","",IFERROR($D50*F50,"")) -> 0
A51: j | B51: 25A 4P MCB in metallic enclosure -IP 65 | C51: Nos | D51: 0 | E51: 4764 | F51: 750 | G51: =IF($D51="","",IFERROR($D51*E51,"")) -> 0 | H51: =IF($D51="","",IFERROR($D51*F51,"")) -> 0
A52: i1 | B52: 20A 4P MCB in metallic enclosure -IP 42 | C52: Nos | D52: 0 | E52: 4764 | F52: 750 | G52: =IF($D52="","",IFERROR($D52*E52,"")) -> 0 | H52: =IF($D52="","",IFERROR($D52*F52,"")) -> 0
A53: j2 | B53: 20A 4P MCB in metallic enclosure -IP 65 (Isolator Type) | C53: Nos | D53: =2*0 -> 0 | E53: 4764 | F53: 750 | G53: =IF($D53="","",IFERROR($D53*E53,"")) -> 0 | H53: =IF($D53="","",IFERROR($D53*F53,"")) -> 0
A54: k | B54: 63A DP MCB in metallic enclosure -IP 42 | C54: Nos | D54: =2*0 -> 0 | E54: 3544 | F54: 750 | G54: =IF($D54="","",IFERROR($D54*E54,"")) -> 0 | H54: =IF($D54="","",IFERROR($D54*F54,"")) -> 0
...

Sheet Electrical - Indegene
A1: Project: Indegene_3F | I1: Date : 27.01.2026
A2: Electrical Works | I2: Rev No : R1
A4: Sl No | B4: ITEM DESCRIPTION | C4: UNIT | D4: Total QTY | E4: Rate | G4: Total Amount (Supply) | H4: Total Amount (Installation) | I4: Remarks
D5: Total | E5: Supply | F5: Installation
A7: 1 | B7: LT SWITCHGEAR
B9: Installation, testing and commissioning of Low voltage switchgear's, free standing, Cubical type, dead front, Frame and Doors:2mm, Internal Partations:1.6mm thick, Gland Plates:3mm Thick, powder coated (Paint Shade: RAL 7032/7035), indoor type with vermin proof hinged lockable doors for each compartment, bus bar interconnections for incoming and outgoing including feeders earthing and painting and as per specifications comprising of ACB,MCCB and MCB horizontal and vertical aluminum bus bar, earth bus bar as per SLD. All meters shall be digital with LED display, whereever mentioned and shall have RS 485 Modbus RTU half duplex communication interface for provision of BMS connectivity and wired accordingly. Provide required NO/NC potential free contacts wires and terminal blocks in the cable alley for BMS operation (Optional).The swtichboards are to be tested as per IS 8623 -1977 specifications. The busbars are of high conductivity Al. alloy E91E IS 5082 specification and cable entries will be from either top or bottom depending on location. LT Switchgear shall be as per technical specification and single line diagram | I9: As Confirmed by client Existing panels are retained and reused.Please quote for Removing and Reinstallation.
A11: 1.1 | B11: MDB -3F(S-1) | C11: Nos | D11: =1 -> 1 | G11: =IF($D11="","",IFERROR($D11*E11,"")) -> 0 | H11: =IF($D11="","",IFERROR($D11*F11,"")) -> 0
B12: MDB -3F (S-1) - Existing Panle modifications as per the Single line diagram and technical specifications.(Indoor -IP 42)
A14: 1.3 | B14: UPS I/P PANEL-1 | C14: Nos | D14: =1 -> 1 | G14: =IF($D14="","",IFERROR($D14*E14,"")) -> 0 | H14: =IF($D14="","",IFERROR($D14*F14,"")) -> 0
B15: UPS I/P PANEL-1 - Existing Panle modifications as per the Single line diagram and technical specifications.(Indoor -IP 42)
A17: 1.4 | B17: UPS I/P PANEL-2 | C17: Nos | D17: =1 -> 1 | G17: =IF($D17="","",IFERROR($D17*E17,"")) -> 0 | H17: =IF($D17="","",IFERROR($D17*F17,"")) -> 0
B18: UPS I/P PANEL-2 - Existing Panle modifications as per the Single line diagram and technical specifications.(Indoor -IP 42)
A20: 1.5 | B20: UPS O/P PANEL-1 | C20: Nos | D20: =1 -> 1 | G20: =IF($D20="","",IFERROR($D20*E20,"")) -> 0 | H20: =IF($D20="","",IFERROR($D20*F20,"")) -> 0
B21: UPS O/P PANEL -1 Existing Panle modifications as per the Single line diagram and technical specifications.(Indoor -IP 42)
A23: 1.6 | B23: UPS O/P PANEL-2 | C23: Nos | D23: =1 -> 1 | G23: =IF($D23="","",IFERROR($D23*E23,"")) -> 0 | H23: =IF($D23="","",IFERROR($D23*F23,"")) -> 0
B24: UPS O/P PANEL -2 Existing Panle modifications as per the Single line diagram and technical specifications.(Indoor -IP 42)
A26: 1.7 | B26: UPS O/P PANEL-3 | C26: Nos | D26: =1 -> 1 | G26: =IF($D26="","",IFERROR($D26*E26,"")) -> 0 | H26: =IF($D26="","",IFERROR($D26*F26,"")) -> 0
B27: UPS O/P PANEL -3 Existing Panle modifications as per the Single line diagram and technical specifications.(Indoor -IP 42)
A29: 1.7 | B29: UPS O/P PANEL-4 | C29: Nos | D29: =1 -> 1 | G29: =IF($D29="","",IFERROR($D29*E29,"")) -> 0 | H29: =IF($D29="","",IFERROR($D29*F29,"")) -> 0
B30: UPS O/P PANEL -3 Existing Panle modifications as per the Single line diagram and technical specifications.(Indoor -IP 42)
A32: 1.8 | B32: VRF AC Panel (Proposed) | C32: Nos | D32: =1 -> 1 | G32: =IF($D32="","",IFERROR($D32*E32,"")) -> 0 | H32: =IF($D32="","",IFERROR($D32*F32,"")) -> 0
B33: VRF AC Panel shall be as per Single line diagram and technical specifications.(Indoor -IP 42)
A35: 1.9 | B35: Kitchen (Proposed) | C35: Nos | D35: =1 -> 1 | G35: =IF($D35="","",IFERROR($D35*E35,"")) -> 0 | H35: =IF($D35="","",IFERROR($D35*F35,"")) -> 0
B36: Kitchen Panel shall be as per Single line diagram and technical specifications.(Indoor -IP 42)
A38: 1.1 | B38: Supply and installation of MCB ISOLATORS
A39: a | B39: 160A 4P MCCB in metallic enclosure -IP 42 (Without Release) | C39: Nos | D39: 4 | G39: =IF($D39="","",IFERROR($D39*E39,"")) -> 0 | H39: =IF($D39="","",IFERROR($D39*F39,"")) -> 0 | I39: 80+80 KVA UPS , 2 Nos (I/O)
A40: b | B40: 80A 4P MCCB in metallic enclosure -IP 42 (Without Release) | C40: Nos | D40: 4 | G40: =IF($D40="","",IFERROR($D40*E40,"")) -> 0 | H40: =IF($D40="","",IFERROR($D40*F40,"")) -> 0 | I40: 40+40 KVA UPS , 2 Nos (I/O)
A41: c | B41: 80A 4P MCB in metallic enclosure -IP 42 | C41: Nos | D41: 0 | G41: =IF($D41="","",IFERROR($D41*E41,"")) -> 0 | H41: =IF($D41="","",IFERROR($D41*F41,"")) -> 0
A42: d | B42: 80A 4P MCB in metallic enclosure -IP 65 | C42: Nos | D42: 0 | G42: =IF($D42="","",IFERROR($D42*E42,"")) -> 0 | H42: =IF($D42="","",IFERROR($D42*F42,"")) -> 0
A43: e | B43: 63A 4P MCB in metallic enclosure -IP 42 | C43: Nos | D43: 0 | G43: =IF($D43="","",IFERROR($D43*E43,"")) -> 0 | H43: =IF($D43="","",IFERROR($D43*F43,"")) -> 0
A44: f | B44: 63A 4P MCB in metallic enclosure -IP 65 (Suitable to terminate 16/25 sqmm Cables) | C44: Nos | D44: =4*0 -> 0 | G44: =IF($D44="","",IFERROR($D44*E44,"")) -> 0 | H44: =IF($D44="","",IFERROR($D44*F44,"")) -> 0
A45: g | B45: 40A 4P MCB in metallic enclosure -IP 42 | C45: Nos | D45: 0 | G45: =IF($D45="","",IFERROR($D45*E45,"")) -> 0 | H45: =IF($D45="","",IFERROR($D45*F45,"")) -> 0
A46: h | B46: 40A 4P MCB in metallic enclosure -IP 65 (Suitable to terminate 16/25 sqmm Cables) | C46: Nos | D46: =10*0 -> 0 | G46: =IF($D46="","",IFERROR($D46*E46,"")) -> 0 | H46: =IF($D46="","",IFERROR($D46*F46,"")) -> 0 | I46: DX ODU&VRF ODU
A47: i | B47: 25A 4P MCB in metallic enclosure -IP 42 | C47: Nos | D47: 0 | G47: =IF($D47="","",IFERROR($D47*E47,"")) -> 0 | H47: =IF($D47="","",IFERROR($D47*F47,"")) -> 0
A48: j | B48: 25A 4P MCB in metallic enclosure -IP 65 | C48: Nos | D48: 0 | G48: =IF($D48="","",IFERROR($D48*E48,"")) -> 0 | H48: =IF($D48="","",IFERROR($D48*F48,"")) -> 0
A49: i1 | B49: 20A 4P MCB in metallic enclosure -IP 42 | C49: Nos | D49: 0 | G49: =IF($D49="","",IFERROR($D49*E49,"")) -> 0 | H49: =IF($D49="","",IFERROR($D49*F49,"")) -> 0
A50: j2 | B50: 20A 4P MCB in metallic enclosure -IP 65 (Isolator Type) | C50: Nos | D50: 0 | G50: =IF($D50="","",IFERROR($D50*E50,"")) -> 0 | H50: =IF($D50="","",IFERROR($D50*F50,"")) -> 0
A51: k | B51: 63A DP MCB in metallic enclosure -IP 42 | C51: Nos | D51: 2 | G51: =IF($D51="","",IFERROR($D51*E51,"")) -> 0 | H51: =IF($D51="","",IFERROR($D51*F51,"")) -> 0 | I51: Inverter
A52: l | B52: 63A DP MCB in metallic enclosure -IP 65 | C52: Nos | D52: 0 | G52: =IF($D52="","",IFERROR($D52*E52,"")) -> 0 | H52: =IF($D52="","",IFERROR($D52*F52,"")) -> 0
A53: m | B53: 40A DP MCB in metallic enclosure -IP 42 | C53: Nos | D53: 0 | G53: =IF($D53="","",IFERROR($D53*E53,"")) -> 0 | H53: =IF($D53="","",IFERROR($D53*F53,"")) -> 0
...

Sheet UPS-Indegene
A1: Project: Indegene_3F | I1: Date : 11.11.2025
A2: Scope of Work : Electrical | I2: Rev No : R0
A3: Purpose - UPS TENDER
A4: Sl No | B4: ITEM DESCRIPTION | C4: UNIT | D4: QTY | E4: Rate | G4: Amount | I4: Remarks
E5: Supply | F5: Installation | G5: Supply | H5: Installation
A7: 1 | B7: Installation , testing and ReCommissioning of EXISTING 80 kVA UPS(Conventional) , 3Ø IN / 3Ø OUT ALONG WITH EXTERNAL ISOLATION TRANSFORMER ,Batteries ,Battery rack, connecting cables from UPS & batteries etc. This Cost Inclusive of Cabling, Breaker etc., | C7: Nos | D7: 1 | G7: =IF($D7="","",IFERROR($D7*E7,"")) -> 0 | H7: =IF($D7="","",IFERROR($D7*F7,"")) -> 0
A8: 2 | B8: Installation , testing and Re Commissioning of EXISTING 40 kVA UPS(Conventional) , 3Ø IN / 3Ø OUT ALONG WITH EXTERNAL ISOLATION TRANSFORMER ,Batteries ,Battery rack, connecting cables from UPS & batteries etc. This Cost Inclusive of Cabling, Breaker etc., | C8: Nos | D8: 1 | G8: =IF($D8="","",IFERROR($D8*E8,"")) -> 0 | H8: =IF($D8="","",IFERROR($D8*F8,"")) -> 0
A9: 3 | B9: Installation , testing and Re Commissioning of EXISTING 10 kVA UPS(Conventional) , 3Ø IN / 1Ø OUT ALONG with Batteries ,Battery rack, connecting cables from UPS & batteries etc. | C9: Nos | D9: 1 | G9: =IF($D9="","",IFERROR($D9*E9,"")) -> 0 | H9: =IF($D9="","",IFERROR($D9*F9,"")) -> 0
A10: 4 | B10: Installation , testing and Re Commissioning of EXISTING 5 / 3 kVA UPS(Conventional) , 1Ø IN / 1Ø OUT ALONG with Batteries ,Battery rack, connecting cables from UPS & batteries etc. This Cost Inclusive of Cabling, Breaker etc., | C10: Nos | D10: 1 | G10: =IF($D10="","",IFERROR($D10*E10,"")) -> 0 | H10: =IF($D10="","",IFERROR($D10*F10,"")) -> 0
B12: Total | G12: =SUM(G7:G11) -> 0 | H12: =SUM(H7:H11) -> 0 | I12: =G12+H12 -> 0
B13: GST
B14: GRAND TOTAL

Sheet IT
A1: ESTIMATION FOR NETWORK
A2: Project: Indegene_3F | H2: Date: | I2: 11.11.2025
A3: Location: | H3: Revision | I3: R0
A4: Project no: | H4: Document No:
A6: S.no | B6: Description | C6: Unit | D6: 3F Qty | E6: Rate | G6: Amount | I6: Remarks
E7: Supply | F7: Installation | G7: Supply | H7: Installation
A8: 1 | B8: DATA
A9: 1.1 | B9: 4-pair, Cat 6 UTP Cable, roll of 305m, Grey | C9: Box | D9: 48 | E9: 16800 | F9: 600 | G9: =IF($E9="","",IFERROR($E9*D9,"")) -> 806400 | H9: =IF($F9="","",IFERROR($F9*D9,"")) -> 28800
A10: 1.2 | B10: Cat 6 UTP Information Outlet for Workstation end | C10: Nos | D10: 210 | E10: 420 | F10: 60 | G10: =IF($E10="","",IFERROR($E10*D10,"")) -> 88200 | H10: =IF($F10="","",IFERROR($F10*D10,"")) -> 12600
A11: 1.3 | B11: Cat6 RJ45-RJ45 UTP Patch Cords, color matched, Yellow - Field end, 7 ft | C11: Nos | D11: =D10:D10 -> 210 | E11: 240 | F11: 12 | G11: =IF($E11="","",IFERROR($E11*D11,"")) -> 50400 | H11: =IF($F11="","",IFERROR($F11*D11,"")) -> 2520
A12: 1.4 | B12: Single Face Plates (80%) | C12: Nos | D12: =D10*0.8 -> 168 | E12: 90 | F12: 24 | G12: =IF($E12="","",IFERROR($E12*D12,"")) -> 15120 | H12: =IF($F12="","",IFERROR($F12*D12,"")) -> 4032
A13: 1.5 | B13: Dual Face Plates (20%) | C13: Nos | D13: =D10*0.1 -> 21 | E13: 96 | F13: 24 | G13: =IF($E13="","",IFERROR($E13*D13,"")) -> 2016 | H13: =IF($F13="","",IFERROR($F13*D13,"")) -> 504
A14: 1.6 | B14: Quad Face Plates | C14: Nos | D14: 0 | E14: 102 | F14: 24 | G14: =IF($E14="","",IFERROR($E14*D14,"")) -> 0 | H14: =IF($F14="","",IFERROR($F14*D14,"")) -> 0
A15: 1.7 | B15: Blank Inserts | C15: Nos | D15: 0 | E15: 18 | F15: 6 | G15: =IF($E15="","",IFERROR($E15*D15,"")) -> 0 | H15: =IF($F15="","",IFERROR($F15*D15,"")) -> 0
A16: 1.8 | B16: Supply and fixing of Metal box suitable information outlet , flush/surface type in position . The rate shall exclude the cost of faceplate and Information Outlet. | C16: Nos | D16: =D10*5% -> 10.5 | E16: 42 | F16: 12 | G16: =IF($E16="","",IFERROR($E16*D16,"")) -> 441 | H16: =IF($F16="","",IFERROR($F16*D16,"")) -> 126
A17: 1.9 | B17: 4-pair, Cat 6 UTP FRLS Cable | C17: Mtrs | D17: 50 | E17: 38 | F17: 14 | G17: =IF($E17="","",IFERROR($E17*D17,"")) -> 1900 | H17: =IF($F17="","",IFERROR($F17*D17,"")) -> 700
A19: =A8+1 -> 2 | B19: HUB ROOM SIDE - DATA
A20: 2.1 | B20: Cat 6 24 Port Angled Discrete Jack panel - fully loaded (1U).The rate shall include the cost of Patch Panel, Information Outlets with all the required supporting accessories. | C20: Nos | D20: 11 | E20: 14400 | F20: 600 | G20: =IF($E20="","",IFERROR($E20*D20,"")) -> 158400 | H20: =IF($F20="","",IFERROR($F20*D20,"")) -> 6600
A21: 2.2 | B21: Cat 6 UTP 10ft patch cords-Jack Panel side - 20% | C21: Nos | D21: =(D20*20)*0.2 -> 44 | E21: 270 | F21: 12 | G21: =IF($E21="","",IFERROR($E21*D21,"")) -> 11880 | H21: =IF($F21="","",IFERROR($F21*D21,"")) -> 528
A22: 2.3 | B22: Cat 6 UTP 7ft patch cords-Jack Panel side - 60% | C22: Nos | D22: =(D20*20)*0.6 -> 132 | E22: 216 | F22: 12 | G22: =IF($E22="","",IFERROR($E22*D22,"")) -> 28512 | H22: =IF($F22="","",IFERROR($F22*D22,"")) -> 1584
A23: 2.4 | B23: Cat 6 UTP 4ft patch cords-Jack Panel side - 20% | C23: Nos | D23: =(D20*20)*0.2 -> 44 | E23: 180 | F23: 12 | G23: =IF($E23="","",IFERROR($E23*D23,"")) -> 7920 | H23: =IF($F23="","",IFERROR($F23*D23,"")) -> 528
A25: =A19+1 -> 3 | B25: VOICE
A26: 3.1 | B26: 4-pair, Cat 6 UTP Cable, roll of 305m, Grey | C26: Box | D26: 4 | E26: 16800 | F26: 360 | G26: =IF($E26="","",IFERROR($E26*D26,"")) -> 67200 | H26: =IF($F26="","",IFERROR($F26*D26,"")) -> 1440
A27: 3.2 | B27: Cat 6 UTP Information Outlet for Workstation end | C27: Nos | D27: 15 | E27: 420 | F27: 60 | G27: =IF($E27="","",IFERROR($E27*D27,"")) -> 6300 | H27: =IF($F27="","",IFERROR($F27*D27,"")) -> 900
A28: 3.3 | B28: Cat6 RJ45-RJ45 UTP Patch Cords, color matched, Yellow - Field end, 7 ft | C28: Nos | D28: =D27:D27 -> 15 | E28: 240 | F28: 12 | G28: =IF($E28="","",IFERROR($E28*D28,"")) -> 3600 | H28: =IF($F28="","",IFERROR($F28*D28,"")) -> 180
A29: 3.4 | B29: Single Face Plates (80%) | C29: Nos | D29: =D27*0.8 -> 12 | E29: 90 | F29: 24 | G29: =IF($E29="","",IFERROR($E29*D29,"")) -> 1080 | H29: =IF($F29="","",IFERROR($F29*D29,"")) -> 288
A30: 3.5 | B30: Dual Face Plates (20%) | C30: Nos | D30: =D27*0.1 -> 1.5 | E30: 96 | F30: 24 | G30: =IF($E30="","",IFERROR($E30*D30,"")) -> 144 | H30: =IF($F30="","",IFERROR($F30*D30,"")) -> 36
A31: 3.6 | B31: Quad Face Plates | C31: Nos | D31: 0 | E31: 102 | F31: 24 | G31: =IF($E31="","",IFERROR($E31*D31,"")) -> 0 | H31: =IF($F31="","",IFERROR($F31*D31,"")) -> 0
A32: 3.7 | B32: Blank Inserts | C32: Nos | D32: 0 | E32: 18 | F32: 6 | G32: =IF($E32="","",IFERROR($E32*D32,"")) -> 0 | H32: =IF($F32="","",IFERROR($F32*D32,"")) -> 0
A33: 3.8 | B33: Supply and fixing of Metal box suitable information outlet , flush/surface type in position . The rate shall exclude the cost of faceplate and Information Outlet. | C33: Nos | D33: =D27*5% -> 0.75 | E33: 42 | F33: 12 | G33: =IF($E33="","",IFERROR($E33*D33,"")) -> 31.5 | H33: =IF($F33="","",IFERROR($F33*D33,"")) -> 9
A34: 3.9 | B34: 4-pair, Cat 6 UTP FRLS Cable | C34: Mtrs | D34: 0 | E34: 54 | F34: 14 | G34: =IF($E34="","",IFERROR($E34*D34,"")) -> 0 | H34: =IF($F34="","",IFERROR($F34*D34,"")) -> 0
A36: =A25+1 -> 4 | B36: HUB ROOM SIDE - VOICE
A37: 4.1 | B37: Cat 6 24 Port Angled Discrete Jack panel - fully loaded (1U).The rate shall include the cost of Patch Panel, Information Outlets with all the required supporting accessories. | C37: Nos | D37: 1 | E37: 9600 | F37: 600 | G37: =IF($E37="","",IFERROR($E37*D37,"")) -> 9600 | H37: =IF($F37="","",IFERROR($F37*D37,"")) -> 600
A38: 4.2 | B38: Cat 6 UTP 10ft patch cords-Jack Panel side - 20% | C38: Nos | D38: =(D37*24)*0.2 -> 4.8 | E38: 270 | F38: 12 | G38: =IF($E38="","",IFERROR($E38*D38,"")) -> 1296 | H38: =IF($F38="","",IFERROR($F38*D38,"")) -> 57.6
A39: 4.3 | B39: Cat 6 UTP 7ft patch cords-Jack Panel side - 60% | C39: Nos | D39: =(D37*24)*0.6 -> 14.4 | E39: 216 | F39: 12 | G39: =IF($E39="","",IFERROR($E39*D39,"")) -> 3110.4 | H39: =IF($F39="","",IFERROR($F39*D39,"")) -> 172.8
A40: 4.4 | B40: Cat 6 UTP 4ft patch cords-Jack Panel side - 20% | C40: Nos | D40: =(D37*24)*0.2 -> 4.8 | E40: 180 | F40: 12 | G40: =IF($E40="","",IFERROR($E40*D40,"")) -> 864 | H40: =IF($F40="","",IFERROR($F40*D40,"")) -> 57.6
A42: 5 | B42: WIFI - DATA | I42: Actual Based on Heat map
A43: 5.1 | B43: 4-pair, Cat 6A UTP Cable, roll of 305m, Grey | C43: Box | D43: 25 | E43: 19200 | F43: 360 | G43: =IF($E43="","",IFERROR($E43*D43,"")) -> 480000 | H43: =IF($F43="","",IFERROR($F43*D43,"")) -> 9000
A44: 5.2 | B44: Cat6A UTP Information Outlet for Workstation end | C44: Nos | D44: =45*2 -> 90 | E44: 330 | F44: 36 | G44: =IF($E44="","",IFERROR($E44*D44,"")) -> 29700 | H44: =IF($F44="","",IFERROR($F44*D44,"")) -> 3240
A45: 5.3 | B45: Cat6A RJ45-RJ45 UTP Patch Cords, color matched, Yellow - Field end, 7 ft | C45: Nos | D45: =D44:D44 -> 90 | E45: 240 | F45: 12 | G45: =IF($E45="","",IFERROR($E45*D45,"")) -> 21600 | H45: =IF($F45="","",IFERROR($F45*D45,"")) -> 1080
...

Sheet CCTV
A2: ESTIMATION FOR CCTV
A3: Project: Indegene_3F | H3: Date: | I3: 11.11.2025
A4: Location: | H4: Revision | I4: R0
A5: Project no: | H5: Document No:
A7: S.no | B7: Description | C7: Unit | D7: Qty | E7: Rate | G7: Amount | I7: Remarks
E8: Supply | F8: Installation | G8: Supply | H8: Installation
A9: 1 | B9: UL approved, Dome Indoor type 2MP,Ceiling/Wall/Surface Mounted ,1920x1080@30fps resolution Dome type network Camera, 15m IR Distance 2.8 - 12 mm Verofocal Lens @ F1.6 & 120dB Wide Dynamic Range, H.264, H.265/MJPEG, WDR, 1/3”Progressive CMOS, Fixed-focal, (Field of View-90°),IR cut filter 12V DC & PoE(802.3af), Day / Night ,on board storage facility.Standards: IP67, IK10, ONVIF, multiple streams, video motion detection, camera tamper alarm, ONVIF compliant,Network Disconnetced ,IP Adress Conflit,Illegal Login,HDD Full,HDD error . The Camera shall be wall / ceiling mounted. The Rate shall include the cost of accessories required for mounting the cameras | C9: Nos | D9: =85*0 -> 0 | E9: 6000 | F9: 240 | G9: =IF($D9="","",IFERROR($D9*E9,"")) -> 0 | H9: =IF($D9="","",IFERROR($D9*F9,"")) -> 0
A10: 2 | B10: UL approved, Out door type (IP 66) 2MP 30fps resolution IR Bullet type Network Camera, (Field of View-60°) 15m IR Distance 2.8 - 12 mm @ F1.4, motorized lens (-Z) & 120dB Wide Dynamic Range, H.265, H.265+, 12V DC & PoE(802.3af), Min. Illumination 0.005 lux @(F1.2, AGC ON), Shutter Speed 1/30 s ~ /100,000s, IR cut filter with auto switch, ONVIF Profile S, PSIA, CGI, 3D Digital noise reduction (video motion detection, camera tamper alarm, ONVIF compliant, and NEMA 4X-rated Housing).The Camera shall be wall / ceiling mounted. The Rate shall include the cost of accessories required for mounting the cameras | C10: Nos | D10: =1*0 -> 0 | E10: 17400 | F10: 900 | G10: =IF($D10="","",IFERROR($D10*E10,"")) -> 0 | H10: =IF($D10="","",IFERROR($D10*F10,"")) -> 0
